<mujoco model="ur5e">
  <compiler angle="radian" autolimits="true"/>

  <option integrator="implicitfast"/>

  <default>
    <include file="../ur5e_2f85_utils/ur5e_classes.xml"/>
    <include file="../ur5e_2f85_utils/2f85_classes.xml"/>
  </default>

  <asset>
    <include file="../ur5e_2f85_utils/ur5e_assets.xml" />
    <include file="../ur5e_2f85_utils/2f85_assets.xml" />
    
    <material name="white" rgba="1 1 1 1"/>
    <material name="off_white" rgba="0.901961 0.921569 0.929412 1"/>
    <material name="dark_grey" rgba="0.25 0.25 0.25 1"/>
    <material name="green" rgba="0 1 0 1"/>
    <material name="light_blue" rgba="0.039216 0.541176 0.780392 1"/>

  </asset>

  <worldbody>
  
    <!-- <body name="ur5e/base" pos="0 0 0" quat="1 0 0 0" childclass="ur5e"> -->
    <body name="ur5e_base" pos="0.8 0.6 0.745" quat="1 0 0 0" childclass="ur5e">
      <inertial mass="4.0" pos="0 0 0" diaginertia="0.00443333156 0.00443333156 0.0072"/>
      <geom mesh="base_0" material="black" class="visual"/>
      <geom mesh="base_1" material="jointgray" class="visual"/>
      <body name="shoulder_link" pos="0 0 0.163">
        <inertial mass="3.7" pos="0 0 0" diaginertia="0.0102675 0.0102675 0.00666"/>
        <joint name="shoulder_pan_joint" class="size3" axis="0 0 1"/>
        <site name="shoulder_pan_joint"/>
        <geom mesh="shoulder_0" material="urblue" class="visual"/>
        <geom mesh="shoulder_1" material="black" class="visual"/>
        <geom mesh="shoulder_2" material="jointgray" class="visual"/>
        <geom class="collision" size="0.06 0.06" pos="0 0 -0.04"/>
        <body name="upper_arm_link" pos="0 0.138 0" quat="1 0 0 0">
          <inertial mass="8.393" pos="0 0 0.2125" diaginertia="0.133886 0.133886 0.0151074"/>
          <joint name="shoulder_lift_joint" class="size3"/>
          <site name="shoulder_lift_joint"/>
          <geom mesh="upperarm_0" material="linkgray" class="visual"/>
          <geom mesh="upperarm_1" material="black" class="visual"/>
          <geom mesh="upperarm_2" material="jointgray" class="visual"/>
          <geom mesh="upperarm_3" material="urblue" class="visual"/>
          <geom class="collision" pos="0 -0.04 0" quat="1 1 0 0" size="0.06 0.06"/>
          <geom class="collision" size="0.05 0.2" pos="0 0 0.2"/>
          <body name="forearm_link" pos="0 -0.131 0.425">
            <inertial mass="2.275" pos="0 0 0.196" diaginertia="0.0311796 0.0311796 0.004095"/>
            <joint name="elbow_joint" class="size3_limited"/>
            <site name="elbow_joint"/>
            <geom mesh="forearm_0" material="urblue" class="visual"/>
            <geom mesh="forearm_1" material="linkgray" class="visual"/>
            <geom mesh="forearm_2" material="black" class="visual"/>
            <geom mesh="forearm_3" material="jointgray" class="visual"/>
            <geom class="collision" pos="0 0.08 0" quat="1 1 0 0" size="0.055 0.06"/>
            <geom class="collision" size="0.038 0.19" pos="0 0 0.2"/>
            <body name="wrist_1_link" pos="0 0 0.392" quat="1 0 0 0">
              <inertial mass="1.219" pos="0 0.127 0" diaginertia="0.0025599 0.0025599 0.0021942"/>
              <joint name="wrist_1_joint" class="size1"/>
              <site name="wrist_1_joint"/>
              <geom mesh="wrist1_0" material="black" class="visual"/>
              <geom mesh="wrist1_1" material="urblue" class="visual"/>
              <geom mesh="wrist1_2" material="jointgray" class="visual"/>
              <geom class="collision" pos="0 0.05 0" quat="1 1 0 0" size="0.04 0.07"/>
              <body name="wrist_2_link" pos="0 0.127 0">
                <inertial mass="1.219" pos="0 0 0.1" diaginertia="0.0025599 0.0025599 0.0021942"/>
                <joint name="wrist_2_joint" axis="0 0 1" class="size1"/>
                <site name="wrist_2_joint"/>
                <geom mesh="wrist2_0" material="black" class="visual"/>
                <geom mesh="wrist2_1" material="urblue" class="visual"/>
                <geom mesh="wrist2_2" material="jointgray" class="visual"/>
                <geom class="collision" size="0.04 0.06" pos="0 0 0.04"/>
                <geom class="collision" pos="0 0.02 0.1" quat="1 1 0 0" size="0.04 0.04"/>
                <body name="wrist_3_link" pos="0 0 0.1">
                  <inertial mass="0.1879" pos="0 0.0771683 0" quat="1 0 0 1"
                    diaginertia="0.000132134 9.90863e-05 9.90863e-05"/>
                  <joint name="wrist_3_joint" class="size1"/>
                  <site name="wrist_3_joint"/>
                  <geom material="linkgray" mesh="wrist3" class="visual"/>
                  <geom class="eef_collision" pos="0 0.08 0" quat="1 1 0 0" size="0.04 0.02"/>
                    <body name="flange" pos="0 0.1 0" quat="1 -1 0 0">
                        <site name="tcp" pos="0 0 0" size="0.01" rgba="0 1 0 0.5" group="2" />
                    </body>
                  <!-- begin of 2f85 -->
                  <body name="attachment" pos="0 0.1 0" quat="-1 1 1 1">
                    <site name="attachment_site" rgba="1 0 0 1" size="0.01" group="1"/>
                    <!-- original description: <body name="2f85_base" pos="0 0 0.007" childclass="2f85"> -->
                    <body name="base_mount" quat="1 0 0 1" childclass="2f85">
                      <geom class="2f85/visual" mesh="base_mount" material="2f85/black"/>
                      <geom class="2f85/collision" mesh="base_mount"/>
                      <body name="base" pos="0 0 0.0038" quat="1 0 0 -1">
                        <inertial mass="0.777441" pos="0 -2.70394e-05 0.0354675" quat="1 -0.00152849 0 0"
                          diaginertia="0.000260285 0.000225381 0.000152708"/>
                        <geom class="2f85/visual" mesh="base" material="2f85/black"/>
                        <geom class="2f85/collision" mesh="base"/>
                        <!-- original description: <site name="pinch" pos="0 0 0.145" type="sphere" group="5" rgba="0.9 0.9 0.9 1" size="0.005"/> -->
                        <site name="pinch" pos="0 0 0.145"/>
                        <body name="right_driver" pos="0 0.0306011 0.054904">
                          <inertial mass="0.00899563" pos="2.96931e-12 0.0177547 0.00107314"
                            quat="0.681301 0.732003 0 0"
                            diaginertia="1.72352e-06 1.60906e-06 3.22006e-07"/>
                          <joint name="right_driver_joint" class="driver"/>
                          <geom class="2f85/visual" mesh="driver" material="gray"/>
                          <geom class="2f85/collision" mesh="driver"/>
                          <body name="right_coupler" pos="0 0.0315 -0.0041">
                            <inertial mass="0.0140974" pos="0 0.00301209 0.0232175"
                              quat="0.705636 -0.0455904 0.0455904 0.705636"
                              diaginertia="4.16206e-06 3.52216e-06 8.88131e-07"/>
                            <joint name="right_coupler_joint" class="coupler"/>
                            <geom class="2f85/visual" mesh="coupler" material="2f85/black"/>
                            <geom class="2f85/collision" mesh="coupler"/>
                          </body>
                        </body>
                        <body name="right_spring_link" pos="0 0.0132 0.0609">
                          <inertial mass="0.0221642" pos="-8.65005e-09 0.0181624 0.0212658"
                            quat="0.663403 -0.244737 0.244737 0.663403"
                            diaginertia="8.96853e-06 6.71733e-06 2.63931e-06"/>
                          <joint name="right_spring_link_joint" class="spring_link"/>
                          <geom class="2f85/visual" mesh="spring_link" material="2f85/black"/>
                          <geom class="2f85/collision" mesh="spring_link"/>
                          <body name="right_follower" pos="0 0.055 0.0375">
                            <inertial mass="0.0125222" pos="0 -0.011046 0.0124786" quat="1 0.1664 0 0"
                              diaginertia="2.67415e-06 2.4559e-06 6.02031e-07"/>
                            <joint name="right_follower_joint" class="follower"/>
                            <geom class="2f85/visual" mesh="follower" material="2f85/black"/>
                            <geom class="2f85/collision" mesh="follower"/>
                            <body name="right_pad" pos="0 -0.0189 0.01352">
                              <geom class="pad_box1" name="right_pad1"/>
                              <geom class="pad_box2" name="right_pad2"/>
                              <inertial mass="0.0035" pos="0 -0.0025 0.0185" quat="0.707107 0 0 0.707107"
                                diaginertia="4.73958e-07 3.64583e-07 1.23958e-07"/>
                              <geom class="2f85/visual" mesh="pad"/>
                              <body name="right_silicone_pad">
                                <geom class="2f85/visual" mesh="silicone_pad" material="2f85/black"/>
                              </body>
                            </body>
                          </body>
                        </body>
                        <body name="left_driver" pos="0 -0.0306011 0.054904" quat="0 0 0 1">
                          <inertial mass="0.00899563" pos="0 0.0177547 0.00107314" quat="0.681301 0.732003 0 0"
                            diaginertia="1.72352e-06 1.60906e-06 3.22006e-07"/>
                          <joint name="left_driver_joint" class="driver"/>
                          <geom class="2f85/visual" mesh="driver" material="gray"/>
                          <geom class="2f85/collision" mesh="driver"/>
                          <body name="left_coupler" pos="0 0.0315 -0.0041">
                            <inertial mass="0.0140974" pos="0 0.00301209 0.0232175"
                              quat="0.705636 -0.0455904 0.0455904 0.705636"
                              diaginertia="4.16206e-06 3.52216e-06 8.88131e-07"/>
                            <joint name="left_coupler_joint" class="coupler"/>
                            <geom class="2f85/visual" mesh="coupler" material="2f85/black"/>
                            <geom class="2f85/collision" mesh="coupler"/>
                          </body>
                        </body>
                        <body name="left_spring_link" pos="0 -0.0132 0.0609" quat="0 0 0 1">
                          <inertial mass="0.0221642" pos="-8.65005e-09 0.0181624 0.0212658"
                            quat="0.663403 -0.244737 0.244737 0.663403"
                            diaginertia="8.96853e-06 6.71733e-06 2.63931e-06"/>
                          <joint name="left_spring_link_joint" class="spring_link"/>
                          <geom class="2f85/visual" mesh="spring_link" material="2f85/black"/>
                          <geom class="2f85/collision" mesh="spring_link"/>
                          <body name="left_follower" pos="0 0.055 0.0375">
                            <inertial mass="0.0125222" pos="0 -0.011046 0.0124786" quat="1 0.1664 0 0"
                              diaginertia="2.67415e-06 2.4559e-06 6.02031e-07"/>
                            <joint name="left_follower_joint" class="follower"/>
                            <geom class="2f85/visual" mesh="follower" material="2f85/black"/>
                            <geom class="2f85/collision" mesh="follower"/>
                            <body name="left_pad" pos="0 -0.0189 0.01352">
                              <geom class="pad_box1" name="left_pad1"/>
                              <geom class="pad_box2" name="left_pad2"/>
                              <inertial mass="0.0035" pos="0 -0.0025 0.0185" quat="1 0 0 1"
                                diaginertia="4.73958e-07 3.64583e-07 1.23958e-07"/>
                              <geom class="2f85/visual" mesh="pad"/>
                              <body name="left_silicone_pad">
                                <geom class="2f85/visual" mesh="silicone_pad" material="2f85/black"/>
                              </body>
                            </body>
                          </body>
                        </body>
                      </body>
                    </body>
                  </body>
                </body>
              </body>
            </body>
          </body>
        </body>
      </body>
    </body>
  </worldbody>

  <contact>
    <!-- exclude 2f85 self-collision  -->
    <exclude body1="base" body2="left_driver"/>
    <exclude body1="base" body2="right_driver"/>
    <exclude body1="base" body2="left_spring_link"/>
    <exclude body1="base" body2="right_spring_link"/>
    <exclude body1="right_coupler" body2="right_follower"/>
    <exclude body1="left_coupler" body2="left_follower"/>
    <!-- exclue ur5e-2f85 self-collision-->
    <exclude body1="flange" body2="base_mount" />
    <exclude body1="wrist_3_link" body2="base_mount" />
    <exclude body1="wrist_2_link" body2="base_mount" />
  </contact>

  <tendon>
    <fixed name="split">
      <joint joint="right_driver_joint" coef="0.5"/>
      <joint joint="left_driver_joint" coef="0.5"/>
    </fixed>
  </tendon>

  <equality>
    <connect anchor="0 0 0" body1="right_follower" body2="right_coupler" solimp="0.95 0.99 0.001" solref="0.005 1"/>
    <connect anchor="0 0 0" body1="left_follower" body2="left_coupler" solimp="0.95 0.99 0.001" solref="0.005 1"/>
    <joint joint1="right_driver_joint" joint2="left_driver_joint" polycoef="0 1 0 0 0" solimp="0.95 0.99 0.001"
      solref="0.005 1"/>
  </equality>

  <actuator>
    <general class="size3" name="shoulder_pan" joint="shoulder_pan_joint"/>
    <general class="size3" name="shoulder_lift" joint="shoulder_lift_joint"/>
    <general class="size3_limited" name="elbow" joint="elbow_joint"/>
    <general class="size1" name="wrist_1" joint="wrist_1_joint"/>
    <general class="size1" name="wrist_2" joint="wrist_2_joint"/>
    <general class="size1" name="wrist_3" joint="wrist_3_joint"/>
    <!--
        The general actuator below is a customized position actuator (with some damping) where
        gainprm[0] != kp (see http://mujoco.org/book/modeling.html#position).
        The reason why gainprm[0] != kp is because the control input range has to be re-scaled to
        [0, 255]. The joint range is currently set at [0, 0.8], the control range is [0, 255] and
        kp = 100. Tau = Kp * scale * control_input - Kp * error, max(Kp * scale * control_input) = 0.8,
        hence scale = 0.8 * 100 / 255
    -->
    <!-- <general class="2f85" name="fingers_actuator" tendon="split" forcerange="-5 5" ctrlrange="0 255"
            gainprm="0.3137255 0 0" biasprm="0 -100 -10"/> -->
    <general class="2f85" name="fingers_actuator"
            tendon="split"
            ctrllimited="true" ctrlrange="0 255"
            forcelimited="true" forcerange="-10 10"
            gainprm="0.3137255 0 0" biasprm="0 -100 -10"/>
  </actuator>
</mujoco>